INFO  - 2024-01-23 11:52:25,908 - client : logging in using static token
INFO  - 2024-01-23 11:52:26,634 - gateway : Shard ID None has connected to Gateway (Session ID: 0bdf8447be6a060732f8782fd5aadb3f).
ERROR - 2024-01-23 11:52:29,561 - client : Ignoring exception in on_ready
Traceback (most recent call last):
  File "E:\anaconda3\Lib\site-packages\discord\ext\commands\bot.py", line 935, in _load_from_module_spec
    spec.loader.exec_module(lib)  # type: ignore
    ^^^^^^^^^^^^^^^^^^^^^^^^^^^^
  File "<frozen importlib._bootstrap_external>", line 940, in exec_module
  File "<frozen importlib._bootstrap>", line 241, in _call_with_frames_removed
  File "E:\python_projects\porkchop\cogs\Twitch.py", line 32, in <module>
    'Authorization':'Bearer ' + keys['access_token']
                                ~~~~^^^^^^^^^^^^^^^^
KeyError: 'access_token'

The above exception was the direct cause of the following exception:

Traceback (most recent call last):
  File "E:\anaconda3\Lib\site-packages\discord\client.py", line 441, in _run_event
    await coro(*args, **kwargs)
  File "E:\python_projects\porkchop\main.py", line 33, in on_ready
    await bot.load_extension(f"cogs.{cog_file.name[:-3]}")
  File "E:\anaconda3\Lib\site-packages\discord\ext\commands\bot.py", line 1013, in load_extension
    await self._load_from_module_spec(spec, name)
  File "E:\anaconda3\Lib\site-packages\discord\ext\commands\bot.py", line 938, in _load_from_module_spec
    raise errors.ExtensionFailed(key, e) from e
discord.ext.commands.errors.ExtensionFailed: Extension 'cogs.Twitch' raised an error: KeyError: 'access_token'
